Workbook

Sheet Calculation
C1: Prediction Period | D1: 46054 | E1: 46060 | F1: 46052 | G1: 46061
C2: Last Month Same Period | D2: 46026 | E2: 46032
C3: Last Year Same Period | D3: 45690 | E3: 45696
C5: Product Sale of Last Month Same Period | D5: 240382.9
C6: Product Sale of Last Year Same Period | D6: 245673.91
C7: Expecting Sales Increase | D7: 0.05
C8: Projected Product Sale | D8: =D6+(D6*D7) -> 257957.61
A11: product_id | B11: supplier_id | C11: product_name | D11: product_group_ID | E11: inventory_unit | F11: purchase_price | G11: Number Of Units in One Case/Package | H11: Usage Last Month Same Period | I11: Opening Inventory 1st Feb 2026 | J11: UPT | K11: Projection | L11: Number of Units need to be ordered | M11: No of cases needs to be ordered
A12: 1 | B12: 52 | C12: BB REGULAR BUNS | D12: 1 | E12: EA | F12: 27.76 | G12: 60 | H12: =IFERROR(VLOOKUP(A12,Usage!L:M,2,FALSE),0) -> 3472 | I12: {=IFERROR(VLOOKUP(A12:A438,'Closing Stock 31st Jan'!A:E,5,FALSE),0)} -> 284 | J12: =H12/($D$5/1000) -> 14.443623 | K12: =J12*($D$8/1000) -> 3725.8424 | L12: =K12-I12 -> 3441.8424 | M12: =L12/G12 -> 57.36404
A13: 2 | B13: 52 | C13: BUNS BIG TASTY 5" | D13: 1 | E13: EA | F13: 20.92 | G13: 40 | H13: =IFERROR(VLOOKUP(A13,Usage!L:M,2,FALSE),0) -> 611 | I13: 117 | J13: =H13/($D$5/1000) -> 2.5417781 | K13: =J13*($D$8/1000) -> 655.671 | L13: =K13-I13 -> 538.671 | M13: =L13/G13 -> 13.466775
A14: 3 | B14: 52 | C14: BB BIGMAC BUNS | D14: 1 | E14: EA | F14: 18.97 | G14: 30 | H14: =IFERROR(VLOOKUP(A14,Usage!L:M,2,FALSE),0) -> 983 | I14: 191 | J14: =H14/($D$5/1000) -> 4.0893092 | K14: =J14*($D$8/1000) -> 1054.8684 | L14: =K14-I14 -> 863.8684 | M14: =L14/G14 -> 28.795613
A15: 4 | B15: 51 | C15: FRENCH FRIES LW | D15: 1 | E15: LB | F15: 134.95 | G15: 36 | H15: =IFERROR(VLOOKUP(A15,Usage!L:M,2,FALSE),0) -> 3760.75 | I15: 2496 | J15: =H15/($D$5/1000) -> 15.644832 | K15: =J15*($D$8/1000) -> 4035.7033 | L15: =K15-I15 -> 1539.7033 | M15: =L15/G15 -> 42.769536
A16: 8 | B16: 51 | C16: FILET-O-FISH PATTY | D16: 1 | E16: EA | F16: 499.31 | G16: 270 | H16: =IFERROR(VLOOKUP(A16,Usage!L:M,2,FALSE),0) -> 0 | I16: 0 | J16: =H16/($D$5/1000) -> 0 | K16: =J16*($D$8/1000) -> 0 | L16: =K16-I16 -> 0 | M16: =L16/G16 -> 0
A17: 10 | B17: 51 | C17: BIGTASTY SAUCE POUCH | D17: 1 | E17: TUB | F17: 358.48 | G17: 30 | H17: =IFERROR(VLOOKUP(A17,Usage!L:M,2,FALSE),0) -> 26.32 | I17: 130 | J17: =H17/($D$5/1000) -> 0.10949198 | K17: =J17*($D$8/1000) -> 28.244289 | L17: =K17-I17 -> -101.75571 | M17: =L17/G17 -> -3.391857
A18: 12 | B18: 51 | C18: MIX SUNDAE | D18: 1 | E18: LTR | F18: 77.58 | G18: 10 | H18: =IFERROR(VLOOKUP(A18,Usage!L:M,2,FALSE),0) -> 96 | I18: 400 | J18: =H18/($D$5/1000) -> 0.39936285 | K18: =J18*($D$8/1000) -> 103.01868 | L18: =K18-I18 -> -296.98132 | M18: =L18/G18 -> -29.698132
A19: 13 | B19: 51 | C19: CHEESE SLICES | D19: 1 | E19: SLC | F19: 372.52 | G19: 1280 | H19: =IFERROR(VLOOKUP(A19,Usage!L:M,2,FALSE),0) -> 4567 | I19: 6320 | J19: =H19/($D$5/1000) -> 18.998856 | K19: =J19*($D$8/1000) -> 4900.8993 | L19: =K19-I19 -> -1419.1007 | M19: =L19/G19 -> -1.1086724
A20: 3236 | B20: 51 | C20: CHEESE EMMENTAL | D20: 1 | E20: SLC | F20: 395.39 | G20: 1280 | H20: =IFERROR(VLOOKUP(A20,Usage!L:M,2,FALSE),0) -> 3881 | I20: 4360 | J20: =H20/($D$5/1000) -> 16.145075 | K20: =J20*($D$8/1000) -> 4164.7449 | L20: =K20-I20 -> -195.25506 | M20: =L20/G20 -> -0.15254301
A21: 19 | B21: 51 | C21: SYRUP COCA COLA | D21: 1 | E21: LTR | F21: 292.57 | G21: 20 | H21: =IFERROR(VLOOKUP(A21,Usage!L:M,2,FALSE),0) -> 322.77 | I21: 160 | J21: =H21/($D$5/1000) -> 1.3427328 | K21: =J21*($D$8/1000) -> 346.36813 | L21: =K21-I21 -> 186.36813 | M21: =L21/G21 -> 9.3184067
A22: 20 | B22: 52 | C22: BB QUARTER BUNS | D22: 1 | E22: EA | F22: 29.39 | G22: 60 | H22: =IFERROR(VLOOKUP(A22,Usage!L:M,2,FALSE),0) -> 2043 | I22: 231 | J22: =H22/($D$5/1000) -> 8.4989406 | K22: =J22*($D$8/1000) -> 2192.3664 | L22: =K22-I22 -> 1961.3664 | M22: =L22/G22 -> 32.68944
A23: 21 | B23: 51 | C23: SYRUP FANTA ORANGE | D23: 1 | E23: LTR | F23: 139.25 | G23: 10 | H23: =IFERROR(VLOOKUP(A23,Usage!L:M,2,FALSE),0) -> 38.49 | I23: 58 | J23: =H23/($D$5/1000) -> 0.16011954 | K23: =J23*($D$8/1000) -> 41.304054 | L23: =K23-I23 -> -16.695946 | M23: =L23/G23 -> -1.6695946
A24: 23 | B24: 51 | C24: ICECREAM CONE FORSAN | D24: 1 | E24: EA | F24: 84.32 | G24: 952 | H24: =IFERROR(VLOOKUP(A24,Usage!L:M,2,FALSE),0) -> 563 | I24: 2454 | J24: =H24/($D$5/1000) -> 2.3420967 | K24: =J24*($D$8/1000) -> 604.16166 | L24: =K24-I24 -> -1849.8383 | M24: =L24/G24 -> -1.9431075
... A142: 1637 | B142: 51 | C142: CHICKEN BURGER MALAY | D142: 1 | E142: EA | F142: 340.43 | G142: 320 | H142: =IFERROR(VLOOKUP(A142,Usage!L:M,2,FALSE),0) -> 5204 | I142: 4598 | J142: =H142/($D$5/1000) -> 21.648794 | K142: =J142*($D$8/1000) -> 5584.4712 | L142: =K142-I142 -> 986.47119 | M142: =L142/G142 -> 3.0827225
A143: 99929 | B143: 51 | C143: SALT FINE | D143: 3 | F143: 33.62 | G143: 1000 | H143: =IFERROR(VLOOKUP(A143,Usage!L:M,2,FALSE),0) -> 0 | I143: 0 | J143: =H143/($D$5/1000) -> 0 | K143: =J143*($D$8/1000) -> 0 | L143: =K143-I143 -> 0 | M143: =L143/G143 -> 0
A144: 10264 | B144: 51 | C144: CHOCOLATE FRAPPE | D144: 1 | E144: EA | F144: 415.41 | G144: 8 | H144: =IFERROR(VLOOKUP(A144,Usage!L:M,2,FALSE),0) -> 1.47 | I144: 6.51 | J144: =H144/($D$5/1000) -> 0.0061152436 | K144: =J144*($D$8/1000) -> 1.5774736 | L144: =K144-I144 -> -4.9325264 | M144: =L144/G144 -> -0.6165658
A145: 4853 | B145: 51 | C145: FC SPICY MCHICKEN PT | D145: 1 | E145: EA | F145: 417.9 | G145: 216 | H145: =IFERROR(VLOOKUP(A145,Usage!L:M,2,FALSE),0) -> 822 | I145: 1306 | J145: =H145/($D$5/1000) -> 3.4195444 | K145: =J145*($D$8/1000) -> 882.09749 | L145: =K145-I145 -> -423.90251 | M145: =L145/G145 -> -1.9625116
A146: 736 | B146: 51 | C146: 10 OZ CLEAR CUP | D146: 2 | E146: EA | F146: 145.6 | G146: 1000 | H146: =IFERROR(VLOOKUP(A146,Usage!L:M,2,FALSE),0) -> 509 | I146: 250 | J146: =H146/($D$5/1000) -> 2.1174551 | K146: =J146*($D$8/1000) -> 546.21365 | L146: =K146-I146 -> 296.21365 | M146: =L146/G146 -> 0.29621365
A147: 7333 | B147: 51 | C147: 16OZ PAPER COLD CUP | D147: 2 | E147: EA | F147: 128.95 | G147: 1000 | H147: =IFERROR(VLOOKUP(A147,Usage!L:M,2,FALSE),0) -> 2138 | I147: 3530 | J147: =H147/($D$5/1000) -> 8.8941435 | K147: =J147*($D$8/1000) -> 2294.312 | L147: =K147-I147 -> -1235.688 | M147: =L147/G147 -> -1.235688
A148: 40076 | B148: 51 | C148: CLAMSHELL MCCHICKEN | D148: 2 | E148: EA | F148: 239.33 | G148: 960 | H148: =IFERROR(VLOOKUP(A148,Usage!L:M,2,FALSE),0) -> 1557 | I148: 1360 | J148: =H148/($D$5/1000) -> 6.4771662 | K148: =J148*($D$8/1000) -> 1670.8343 | L148: =K148-I148 -> 310.83429 | M148: =L148/G148 -> 0.32378572
A149: 40077 | B149: 51 | C149: CLMASHELL ROYAL 4" | D149: 2 | E149: EA | F149: 235.65 | G149: 960 | H149: =IFERROR(VLOOKUP(A149,Usage!L:M,2,FALSE),0) -> 88 | I149: 496 | J149: =H149/($D$5/1000) -> 0.36608261 | K149: =J149*($D$8/1000) -> 94.433794 | L149: =K149-I149 -> -401.56621 | M149: =L149/G149 -> -0.41829813
A150: 40078 | B150: 51 | C150: CLAMSHELL QUARTER4" | D150: 2 | E150: EA | F150: 234.68 | G150: 960 | H150: =IFERROR(VLOOKUP(A150,Usage!L:M,2,FALSE),0) -> 31 | I150: 189 | J150: =H150/($D$5/1000) -> 0.12896092 | K150: =J150*($D$8/1000) -> 33.26645 | L150: =K150-I150 -> -155.73355 | M150: =L150/G150 -> -0.16222245
A151: 40079 | B151: 51 | C151: CLAMSHELL SPICY 4" | D151: 2 | E151: EA | F151: 236.46 | G151: 960 | H151: =IFERROR(VLOOKUP(A151,Usage!L:M,2,FALSE),0) -> 0 | I151: 960 | J151: =H151/($D$5/1000) -> 0 | K151: =J151*($D$8/1000) -> 0 | L151: =K151-I151 -> -960 | M151: =L151/G151 -> -1
A152: 808 | B152: 51 | C152: CHARITY BOOKLET | D152: 4 | E152: EA | F152: 0.93 | G152: 1 | H152: =IFERROR(VLOOKUP(A152,Usage!L:M,2,FALSE),0) -> 153 | I152: 1180 | J152: =H152/($D$5/1000) -> 0.63648454 | K152: =J152*($D$8/1000) -> 164.18603 | L152: =K152-I152 -> -1015.814 | M152: =L152/G152 -> -1015.814
A153: 7206 | B153: 51 | C153: SPICY GRAND CHICKEN | D153: 1 | E153: EA | F153: 370.8 | G153: 120 | H153: =IFERROR(VLOOKUP(A153,Usage!L:M,2,FALSE),0) -> 584 | I153: 230 | J153: =H153/($D$5/1000) -> 2.4294573 | K153: =J153*($D$8/1000) -> 626.697 | L153: =K153-I153 -> 396.697 | M153: =L153/G153 -> 3.3058083
A154: 2787 | B154: 51 | C154: PINEAPPLESTICK FROZN | D154: 1 | E154: EA | F154: 1.4 | G154: 1 | H154: =IFERROR(VLOOKUP(A154,Usage!L:M,2,FALSE),0) -> 38 | I154: 81 | J154: =H154/($D$5/1000) -> 0.15808113 | K154: =J154*($D$8/1000) -> 40.778229 | L154: =K154-I154 -> -40.221771 | M154: =L154/G154 -> -40.221771
A155: 6811 | B155: 51 | C155: JALAPENO CHEESEBITES | D155: 1 | E155: EA | F155: 196.08 | G155: 300 | H155: =IFERROR(VLOOKUP(A155,Usage!L:M,2,FALSE),0) -> 1906 | I155: 2976 | J155: =H155/($D$5/1000) -> 7.9290166 | K155: =J155*($D$8/1000) -> 2045.3501 | L155: =K155-I155 -> -930.64987 | M155: =L155/G155 -> -3.1021662
... A262: 99078 | B262: 51 | C262: WET WIPES LIFEBUOY | D262: 4 | E262: EA | F262: 225.67 | G262: 1000 | H262: =IFERROR(VLOOKUP(A262,Usage!L:M,2,FALSE),0) -> 0 | I262: 0 | J262: =H262/($D$5/1000) -> 0 | K262: =J262*($D$8/1000) -> 0 | L262: =K262-I262 -> 0 | M262: =L262/G262 -> 0
A263: 37089 | B263: 51 | C263: WATER BOTTLE C.GIFT | D263: 4 | F263: 17.36 | G263: 1 | H263: =IFERROR(VLOOKUP(A263,Usage!L:M,2,FALSE),0) -> 0 | I263: 0 | J263: =H263/($D$5/1000) -> 0 | K263: =J263*($D$8/1000) -> 0 | L263: =K263-I263 -> 0 | M263: =L263/G263 -> 0
A264: 34120 | B264: 51 | C264: CHIKKER CLAMSHELL | D264: 2 | E264: EA | F264: 143.94 | G264: 450 | H264: =IFERROR(VLOOKUP(A264,Usage!L:M,2,FALSE),0) -> 0 | I264: 0 | J264: =H264/($D$5/1000) -> 0 | K264: =J264*($D$8/1000) -> 0 | L264: =K264-I264 -> 0 | M264: =L264/G264 -> 0
A265: 16564 | B265: 52 | C265: CHIKKER BUNS | D265: 1 | E265: EA | F265: 99.94 | G265: 192 | H265: =IFERROR(VLOOKUP(A265,Usage!L:M,2,FALSE),0) -> 0 | I265: 0 | J265: =H265/($D$5/1000) -> 0 | K265: =J265*($D$8/1000) -> 0 | L265: =K265-I265 -> 0 | M265: =L265/G265 -> 0
A266: 13322 | B266: 51 | C266: CHILI JACK CHEESE | D266: 1 | E266: EA | F266: 237.07 | G266: 640 | H266: =IFERROR(VLOOKUP(A266,Usage!L:M,2,FALSE),0) -> 0 | I266: 0 | J266: =H266/($D$5/1000) -> 0 | K266: =J266*($D$8/1000) -> 0 | L266: =K266-I266 -> 0 | M266: =L266/G266 -> 0
...

Sheet Additional Details
A1: Supplier ID | B1: Supplier Name | F1: product_group_ID | G1: Description
A2: 51 | B2: UFS | F2: 1 | G2: FOOD
A3: 52 | B3: Al Rashed Bakery | F3: 2 | G3: PAPER
A4: 53 | B4: Kanaani Farms | F4: 3 | G4: CONDIMENTS
A5: 54 | B5: Coco-Cola | F5: 4 | G5: NON-PRODUCT
A6: 55 | B6: Del Monte

Sheet Usage
A1: Product_id | B1: location | C1: date | D1: type | E1: quantity | L1: Product_id | M1: Sum of quantity
A2: 1 | B2: 1830197 | C2: 46054 | D2: Sale | E2: 464 | I2: Row Labels | J2: Sum of quantity | L2: 1 | M2: 3472
A3: 2 | B3: 1830197 | C3: 46054 | D3: Sale | E3: 71 | I3: 1 | J3: 3472 | L3: 2 | M3: 611
A4: 3 | B4: 1830197 | C4: 46054 | D4: Sale | E4: 121 | I4: 2 | J4: 611 | L4: 3 | M4: 983
A5: 4 | B5: 1830197 | C5: 46054 | D5: Sale | E5: 494.49 | I5: 3 | J5: 983 | L5: 4 | M5: 3760.75
A6: 5 | B6: 1830197 | C6: 46054 | D6: Sale | E6: 249 | I6: 4 | J6: 3760.75 | L6: 5 | M6: 1623
A7: 6 | B7: 1830197 | C7: 46054 | D7: Sale | E7: 26 | I7: 5 | J7: 1623 | L7: 6 | M7: 144
A8: 7 | B8: 1830197 | C8: 46054 | D8: Sale | E8: 153 | I8: 6 | J8: 144 | L8: 7 | M8: 1309
A9: 8 | B9: 1830197 | C9: 46054 | D9: Sale | E9: 0 | I9: 7 | J9: 1309 | L9: 8 | M9: 0
A10: 9 | B10: 1830197 | C10: 46054 | D10: Sale | E10: 0 | I10: 8 | J10: 0 | L10: 9 | M10: 0
A11: 10 | B11: 1830197 | C11: 46054 | D11: Sale | E11: 4.11 | I11: 9 | J11: 0 | L11: 10 | M11: 26.32
A12: 12 | B12: 1830197 | C12: 46054 | D12: Sale | E12: 10.12 | I12: 10 | J12: 26.32 | L12: 12 | M12: 96
A13: 13 | B13: 1830197 | C13: 46054 | D13: Sale | E13: 588 | I13: 12 | J13: 96 | L13: 13 | M13: 4567
A14: 19 | B14: 1830197 | C14: 46054 | D14: Sale | E14: 40 | I14: 13 | J14: 4567 | L14: 19 | M14: 322.77
... A524: 99999 | B524: 1830197 | C524: 46054 | D524: Sale | E524: 0 | I524: 99996 | J524: 0 | L524: 99999 | M524: 0
A525: 1 | B525: 1830197 | C525: 46055 | D525: Sale | E525: 470 | I525: 99999 | J525: 0
A526: 2 | B526: 1830197 | C526: 46055 | D526: Sale | E526: 58 | I526: (blank)
A527: 3 | B527: 1830197 | C527: 46055 | D527: Sale | E527: 140 | I527: Grand Total | J527: 181140.93
A528: 4 | B528: 1830197 | C528: 46055 | D528: Sale | E528: 469.51
A529: 5 | B529: 1830197 | C529: 46055 | D529: Sale | E529: 263
A530: 6 | B530: 1830197 | C530: 46055 | D530: Sale | E530: 24
A531: 7 | B531: 1830197 | C531: 46055 | D531: Sale | E531: 202
A532: 8 | B532: 1830197 | C532: 46055 | D532: Sale | E532: 0
A533: 9 | B533: 1830197 | C533: 46055 | D533: Sale | E533: 0
A534: 10 | B534: 1830197 | C534: 46055 | D534: Sale | E534: 3
A535: 12 | B535: 1830197 | C535: 46055 | D535: Sale | E535: 9.88
A536: 13 | B536: 1830197 | C536: 46055 | D536: Sale | E536: 637
A537: 19 | B537: 1830197 | C537: 46055 | D537: Sale | E537: 50
A538: 20 | B538: 1830197 | C538: 46055 | D538: Sale | E538: 301
A539: 21 | B539: 1830197 | C539: 46055 | D539: Sale | E539: 6
... A3662: 99999 | B3662: 1830197 | C3662: 46060 | D3662: Sale | E3662: 0

Sheet Closing Stock 31st Jan
A1: Product_id | B1: location | C1: date | D1: type | E1: quantity
A2: 1 | B2: 1830197 | C2: 46053 | D2: BALANCE | E2: 284
A3: 2 | B3: 1830197 | C3: 46053 | D3: BALANCE | E3: 117
A4: 3 | B4: 1830197 | C4: 46053 | D4: BALANCE | E4: 191
A5: 4 | B5: 1830197 | C5: 46053 | D5: BALANCE | E5: 2496
A6: 5 | B6: 1830197 | C6: 46053 | D6: BALANCE | E6: 3641
A7: 6 | B7: 1830197 | C7: 46053 | D7: BALANCE | E7: 720
A8: 7 | B8: 1830197 | C8: 46053 | D8: BALANCE | E8: 1959
A9: 8 | B9: 1830197 | C9: 46053 | D9: BALANCE | E9: 0
A10: 9 | B10: 1830197 | C10: 46053 | D10: BALANCE | E10: 0
A11: 10 | B11: 1830197 | C11: 46053 | D11: BALANCE | E11: 130
A12: 12 | B12: 1830197 | C12: 46053 | D12: BALANCE | E12: 400
A13: 13 | B13: 1830197 | C13: 46053 | D13: BALANCE | E13: 6320
... A524: 99999 | B524: 1830197 | C524: 46053 | D524: BALANCE | E524: 0

Sheet Sheet5
